[2025-08-29T15:47:08.033+0000] {local_task_job_runner.py:120} INFO - ::group::Pre task execution logs
[2025-08-29T15:47:08.072+0000] {taskinstance.py:2076} INFO - Dependencies all met for dep_context=non-requeueable deps ti=<TaskInstance: retail_sales_training_pipeline.train_initial_model manual__2025-08-29T15:47:00.749670+00:00 [queued]>
[2025-08-29T15:47:08.082+0000] {taskinstance.py:2076} INFO - Dependencies all met for dep_context=requeueable deps ti=<TaskInstance: retail_sales_training_pipeline.train_initial_model manual__2025-08-29T15:47:00.749670+00:00 [queued]>
[2025-08-29T15:47:08.083+0000] {taskinstance.py:2306} INFO - Starting attempt 1 of 1
[2025-08-29T15:47:08.102+0000] {taskinstance.py:2330} INFO - Executing <Task(BashOperator): train_initial_model> on 2025-08-29 15:47:00.749670+00:00
[2025-08-29T15:47:08.110+0000] {standard_task_runner.py:90} INFO - Running: ['***', 'tasks', 'run', 'retail_sales_training_pipeline', 'train_initial_model', 'manual__2025-08-29T15:47:00.749670+00:00', '--job-id', '12', '--raw', '--subdir', 'DAGS_FOLDER/model_training_dag.py', '--cfg-path', '/tmp/tmp8_5smeug']
[2025-08-29T15:47:08.113+0000] {standard_task_runner.py:91} INFO - Job 12: Subtask train_initial_model
[2025-08-29T15:47:08.113+0000] {logging_mixin.py:188} WARNING - /home/***/.local/lib/python3.12/site-packages/***/task/task_runner/standard_task_runner.py:61 DeprecationWarning: This process (pid=221) is multi-threaded, use of fork() may lead to deadlocks in the child.
[2025-08-29T15:47:08.114+0000] {standard_task_runner.py:63} INFO - Started process 222 to run task
[2025-08-29T15:47:08.161+0000] {task_command.py:426} INFO - Running <TaskInstance: retail_sales_training_pipeline.train_initial_model manual__2025-08-29T15:47:00.749670+00:00 [running]> on host 18d1d26c7908
[2025-08-29T15:47:08.253+0000] {taskinstance.py:2648} INFO - Exporting env vars: AIRFLOW_CTX_DAG_OWNER='***' AIRFLOW_CTX_DAG_ID='retail_sales_training_pipeline' AIRFLOW_CTX_TASK_ID='train_initial_model' AIRFLOW_CTX_EXECUTION_DATE='2025-08-29T15:47:00.749670+00:00' AIRFLOW_CTX_TRY_NUMBER='1' AIRFLOW_CTX_DAG_RUN_ID='manual__2025-08-29T15:47:00.749670+00:00'
[2025-08-29T15:47:08.255+0000] {taskinstance.py:430} INFO - ::endgroup::
[2025-08-29T15:47:08.270+0000] {subprocess.py:63} INFO - Tmp dir root location: /tmp
[2025-08-29T15:47:08.271+0000] {subprocess.py:75} INFO - Running command: ['/usr/bin/bash', '-c', 'python /opt/***/scripts/train_model.py']
[2025-08-29T15:47:08.280+0000] {subprocess.py:86} INFO - Output:
[2025-08-29T15:47:09.621+0000] {subprocess.py:93} INFO - Importing plotly failed. Interactive plots will not work.
[2025-08-29T15:47:15.510+0000] {subprocess.py:93} INFO - WARNING:urllib3.connectionpool:Retrying (Retry(total=6, connect=6, read=7, redirect=7, status=7)) after connection broken by 'NameResolutionError("<urllib3.connection.HTTPConnection object at 0x7ff613b05c10>: Failed to resolve 'mlflow-server' ([Errno -5] No address associated with hostname)")': /api/2.0/mlflow/experiments/get-by-name?experiment_name=Retail+Sales+Forecasting+-+Docker
[2025-08-29T15:47:24.413+0000] {subprocess.py:93} INFO - WARNING:urllib3.connectionpool:Retrying (Retry(total=5, connect=5, read=7, redirect=7, status=7)) after connection broken by 'NameResolutionError("<urllib3.connection.HTTPConnection object at 0x7ff613b07920>: Failed to resolve 'mlflow-server' ([Errno -5] No address associated with hostname)")': /api/2.0/mlflow/experiments/get-by-name?experiment_name=Retail+Sales+Forecasting+-+Docker
[2025-08-29T15:47:36.593+0000] {subprocess.py:93} INFO - WARNING:urllib3.connectionpool:Retrying (Retry(total=4, connect=4, read=7, redirect=7, status=7)) after connection broken by 'NameResolutionError("<urllib3.connection.HTTPConnection object at 0x7ff5f73ddd00>: Failed to resolve 'mlflow-server' ([Errno -2] Name or service not known)")': /api/2.0/mlflow/experiments/get-by-name?experiment_name=Retail+Sales+Forecasting+-+Docker
[2025-08-29T15:47:57.165+0000] {subprocess.py:93} INFO - WARNING:urllib3.connectionpool:Retrying (Retry(total=3, connect=3, read=7, redirect=7, status=7)) after connection broken by 'NameResolutionError("<urllib3.connection.HTTPConnection object at 0x7ff5f663c5c0>: Failed to resolve 'mlflow-server' ([Errno -5] No address associated with hostname)")': /api/2.0/mlflow/experiments/get-by-name?experiment_name=Retail+Sales+Forecasting+-+Docker
[2025-08-29T15:48:34.104+0000] {subprocess.py:93} INFO - WARNING:urllib3.connectionpool:Retrying (Retry(total=2, connect=2, read=7, redirect=7, status=7)) after connection broken by 'NameResolutionError("<urllib3.connection.HTTPConnection object at 0x7ff5f663c950>: Failed to resolve 'mlflow-server' ([Errno -5] No address associated with hostname)")': /api/2.0/mlflow/experiments/get-by-name?experiment_name=Retail+Sales+Forecasting+-+Docker
[2025-08-29T15:49:42.838+0000] {subprocess.py:93} INFO - WARNING:urllib3.connectionpool:Retrying (Retry(total=1, connect=1, read=7, redirect=7, status=7)) after connection broken by 'NameResolutionError("<urllib3.connection.HTTPConnection object at 0x7ff5f663cb90>: Failed to resolve 'mlflow-server' ([Errno -5] No address associated with hostname)")': /api/2.0/mlflow/experiments/get-by-name?experiment_name=Retail+Sales+Forecasting+-+Docker
[2025-08-29T15:51:46.829+0000] {subprocess.py:93} INFO - WARNING:urllib3.connectionpool:Retrying (Retry(total=0, connect=0, read=7, redirect=7, status=7)) after connection broken by 'NameResolutionError("<urllib3.connection.HTTPConnection object at 0x7ff5f663cdd0>: Failed to resolve 'mlflow-server' ([Errno -5] No address associated with hostname)")': /api/2.0/mlflow/experiments/get-by-name?experiment_name=Retail+Sales+Forecasting+-+Docker
[2025-08-29T15:51:50.831+0000] {subprocess.py:93} INFO - Traceback (most recent call last):
[2025-08-29T15:51:50.832+0000] {subprocess.py:93} INFO -   File "/home/***/.local/lib/python3.12/site-packages/urllib3/connection.py", line 198, in _new_conn
[2025-08-29T15:51:50.833+0000] {subprocess.py:93} INFO -     sock = connection.create_connection(
[2025-08-29T15:51:50.833+0000] {subprocess.py:93} INFO -            ^^^^^^^^^^^^^^^^^^^^^^^^^^^^^
[2025-08-29T15:51:50.834+0000] {subprocess.py:93} INFO -   File "/home/***/.local/lib/python3.12/site-packages/urllib3/util/connection.py", line 60, in create_connection
[2025-08-29T15:51:50.834+0000] {subprocess.py:93} INFO -     for res in socket.getaddrinfo(host, port, family, socket.SOCK_STREAM):
[2025-08-29T15:51:50.834+0000] {subprocess.py:93} INFO -                ^^^^^^^^^^^^^^^^^^^^^^^^^^^^^^^^^^^^^^^^^^^^^^^^^^^^^^^^^^
[2025-08-29T15:51:50.835+0000] {subprocess.py:93} INFO -   File "/usr/local/lib/python3.12/socket.py", line 964, in getaddrinfo
[2025-08-29T15:51:50.835+0000] {subprocess.py:93} INFO -     for res in _socket.getaddrinfo(host, port, family, type, proto, flags):
[2025-08-29T15:51:50.836+0000] {subprocess.py:93} INFO -                ^^^^^^^^^^^^^^^^^^^^^^^^^^^^^^^^^^^^^^^^^^^^^^^^^^^^^^^^^^^
[2025-08-29T15:51:50.836+0000] {subprocess.py:93} INFO - socket.gaierror: [Errno -5] No address associated with hostname
[2025-08-29T15:51:50.836+0000] {subprocess.py:93} INFO - 
[2025-08-29T15:51:50.837+0000] {subprocess.py:93} INFO - The above exception was the direct cause of the following exception:
[2025-08-29T15:51:50.837+0000] {subprocess.py:93} INFO - 
[2025-08-29T15:51:50.838+0000] {subprocess.py:93} INFO - Traceback (most recent call last):
[2025-08-29T15:51:50.838+0000] {subprocess.py:93} INFO -   File "/home/***/.local/lib/python3.12/site-packages/urllib3/connectionpool.py", line 793, in urlopen
[2025-08-29T15:51:50.839+0000] {subprocess.py:93} INFO -     response = self._make_request(
[2025-08-29T15:51:50.839+0000] {subprocess.py:93} INFO -                ^^^^^^^^^^^^^^^^^^^
[2025-08-29T15:51:50.840+0000] {subprocess.py:93} INFO -   File "/home/***/.local/lib/python3.12/site-packages/urllib3/connectionpool.py", line 496, in _make_request
[2025-08-29T15:51:50.840+0000] {subprocess.py:93} INFO -     conn.request(
[2025-08-29T15:51:50.841+0000] {subprocess.py:93} INFO -   File "/home/***/.local/lib/python3.12/site-packages/urllib3/connection.py", line 400, in request
[2025-08-29T15:51:50.841+0000] {subprocess.py:93} INFO -     self.endheaders()
[2025-08-29T15:51:50.842+0000] {subprocess.py:93} INFO -   File "/usr/local/lib/python3.12/http/client.py", line 1331, in endheaders
[2025-08-29T15:51:50.842+0000] {subprocess.py:93} INFO -     self._send_output(message_body, encode_chunked=encode_chunked)
[2025-08-29T15:51:50.843+0000] {subprocess.py:93} INFO -   File "/usr/local/lib/python3.12/http/client.py", line 1091, in _send_output
[2025-08-29T15:51:50.843+0000] {subprocess.py:93} INFO -     self.send(msg)
[2025-08-29T15:51:50.844+0000] {subprocess.py:93} INFO -   File "/usr/local/lib/python3.12/http/client.py", line 1035, in send
[2025-08-29T15:51:50.844+0000] {subprocess.py:93} INFO -     self.connect()
[2025-08-29T15:51:50.845+0000] {subprocess.py:93} INFO -   File "/home/***/.local/lib/python3.12/site-packages/urllib3/connection.py", line 238, in connect
[2025-08-29T15:51:50.845+0000] {subprocess.py:93} INFO -     self.sock = self._new_conn()
[2025-08-29T15:51:50.845+0000] {subprocess.py:93} INFO -                 ^^^^^^^^^^^^^^^^
[2025-08-29T15:51:50.846+0000] {subprocess.py:93} INFO -   File "/home/***/.local/lib/python3.12/site-packages/urllib3/connection.py", line 205, in _new_conn
[2025-08-29T15:51:50.846+0000] {subprocess.py:93} INFO -     raise NameResolutionError(self.host, self, e) from e
[2025-08-29T15:51:50.847+0000] {subprocess.py:93} INFO - urllib3.exceptions.NameResolutionError: <urllib3.connection.HTTPConnection object at 0x7ff5f663d160>: Failed to resolve 'mlflow-server' ([Errno -5] No address associated with hostname)
[2025-08-29T15:51:50.847+0000] {subprocess.py:93} INFO - 
[2025-08-29T15:51:50.847+0000] {subprocess.py:93} INFO - The above exception was the direct cause of the following exception:
[2025-08-29T15:51:50.848+0000] {subprocess.py:93} INFO - 
[2025-08-29T15:51:50.848+0000] {subprocess.py:93} INFO - Traceback (most recent call last):
[2025-08-29T15:51:50.849+0000] {subprocess.py:93} INFO -   File "/home/***/.local/lib/python3.12/site-packages/requests/adapters.py", line 486, in send
[2025-08-29T15:51:50.849+0000] {subprocess.py:93} INFO -     resp = conn.urlopen(
[2025-08-29T15:51:50.849+0000] {subprocess.py:93} INFO -            ^^^^^^^^^^^^^
[2025-08-29T15:51:50.850+0000] {subprocess.py:93} INFO -   File "/home/***/.local/lib/python3.12/site-packages/urllib3/connectionpool.py", line 877, in urlopen
[2025-08-29T15:51:50.850+0000] {subprocess.py:93} INFO -     return self.urlopen(
[2025-08-29T15:51:50.851+0000] {subprocess.py:93} INFO -            ^^^^^^^^^^^^^
[2025-08-29T15:51:50.851+0000] {subprocess.py:93} INFO -   File "/home/***/.local/lib/python3.12/site-packages/urllib3/connectionpool.py", line 877, in urlopen
[2025-08-29T15:51:50.851+0000] {subprocess.py:93} INFO -     return self.urlopen(
[2025-08-29T15:51:50.852+0000] {subprocess.py:93} INFO -            ^^^^^^^^^^^^^
[2025-08-29T15:51:50.852+0000] {subprocess.py:93} INFO -   File "/home/***/.local/lib/python3.12/site-packages/urllib3/connectionpool.py", line 877, in urlopen
[2025-08-29T15:51:50.852+0000] {subprocess.py:93} INFO -     return self.urlopen(
[2025-08-29T15:51:50.853+0000] {subprocess.py:93} INFO -            ^^^^^^^^^^^^^
[2025-08-29T15:51:50.853+0000] {subprocess.py:93} INFO -   [Previous line repeated 4 more times]
[2025-08-29T15:51:50.853+0000] {subprocess.py:93} INFO -   File "/home/***/.local/lib/python3.12/site-packages/urllib3/connectionpool.py", line 847, in urlopen
[2025-08-29T15:51:50.854+0000] {subprocess.py:93} INFO -     retries = retries.increment(
[2025-08-29T15:51:50.854+0000] {subprocess.py:93} INFO -               ^^^^^^^^^^^^^^^^^^
[2025-08-29T15:51:50.855+0000] {subprocess.py:93} INFO -   File "/home/***/.local/lib/python3.12/site-packages/urllib3/util/retry.py", line 515, in increment
[2025-08-29T15:51:50.855+0000] {subprocess.py:93} INFO -     raise MaxRetryError(_pool, url, reason) from reason  # type: ignore[arg-type]
[2025-08-29T15:51:50.856+0000] {subprocess.py:93} INFO -     ^^^^^^^^^^^^^^^^^^^^^^^^^^^^^^^^^^^^^^^^^^^^^^^^^^^
[2025-08-29T15:51:50.856+0000] {subprocess.py:93} INFO - urllib3.exceptions.MaxRetryError: HTTPConnectionPool(host='mlflow-server', port=5000): Max retries exceeded with url: /api/2.0/mlflow/experiments/get-by-name?experiment_name=Retail+Sales+Forecasting+-+Docker (Caused by NameResolutionError("<urllib3.connection.HTTPConnection object at 0x7ff5f663d160>: Failed to resolve 'mlflow-server' ([Errno -5] No address associated with hostname)"))
[2025-08-29T15:51:50.857+0000] {subprocess.py:93} INFO - 
[2025-08-29T15:51:50.857+0000] {subprocess.py:93} INFO - During handling of the above exception, another exception occurred:
[2025-08-29T15:51:50.858+0000] {subprocess.py:93} INFO - 
[2025-08-29T15:51:50.858+0000] {subprocess.py:93} INFO - Traceback (most recent call last):
[2025-08-29T15:51:50.859+0000] {subprocess.py:93} INFO -   File "/home/***/.local/lib/python3.12/site-packages/mlflow/utils/rest_utils.py", line 230, in http_request
[2025-08-29T15:51:50.859+0000] {subprocess.py:93} INFO -     return _get_http_response_with_retries(
[2025-08-29T15:51:50.860+0000] {subprocess.py:93} INFO -            ^^^^^^^^^^^^^^^^^^^^^^^^^^^^^^^^
[2025-08-29T15:51:50.860+0000] {subprocess.py:93} INFO -   File "/home/***/.local/lib/python3.12/site-packages/mlflow/utils/request_utils.py", line 237, in _get_http_response_with_retries
[2025-08-29T15:51:50.861+0000] {subprocess.py:93} INFO -     return session.request(method, url, allow_redirects=allow_redirects, **kwargs)
[2025-08-29T15:51:50.861+0000] {subprocess.py:93} INFO -            ^^^^^^^^^^^^^^^^^^^^^^^^^^^^^^^^^^^^^^^^^^^^^^^^^^^^^^^^^^^^^^^^^^^^^^^
[2025-08-29T15:51:50.862+0000] {subprocess.py:93} INFO -   File "/home/***/.local/lib/python3.12/site-packages/requests/sessions.py", line 589, in request
[2025-08-29T15:51:50.862+0000] {subprocess.py:93} INFO -     resp = self.send(prep, **send_kwargs)
[2025-08-29T15:51:50.863+0000] {subprocess.py:93} INFO -            ^^^^^^^^^^^^^^^^^^^^^^^^^^^^^^
[2025-08-29T15:51:50.863+0000] {subprocess.py:93} INFO -   File "/home/***/.local/lib/python3.12/site-packages/requests/sessions.py", line 703, in send
[2025-08-29T15:51:50.863+0000] {subprocess.py:93} INFO -     r = adapter.send(request, **kwargs)
[2025-08-29T15:51:50.864+0000] {subprocess.py:93} INFO -         ^^^^^^^^^^^^^^^^^^^^^^^^^^^^^^^
[2025-08-29T15:51:50.864+0000] {subprocess.py:93} INFO -   File "/home/***/.local/lib/python3.12/site-packages/requests/adapters.py", line 519, in send
[2025-08-29T15:51:50.865+0000] {subprocess.py:93} INFO -     raise ConnectionError(e, request=request)
[2025-08-29T15:51:50.865+0000] {subprocess.py:93} INFO - requests.exceptions.ConnectionError: HTTPConnectionPool(host='mlflow-server', port=5000): Max retries exceeded with url: /api/2.0/mlflow/experiments/get-by-name?experiment_name=Retail+Sales+Forecasting+-+Docker (Caused by NameResolutionError("<urllib3.connection.HTTPConnection object at 0x7ff5f663d160>: Failed to resolve 'mlflow-server' ([Errno -5] No address associated with hostname)"))
[2025-08-29T15:51:50.866+0000] {subprocess.py:93} INFO - 
[2025-08-29T15:51:50.866+0000] {subprocess.py:93} INFO - During handling of the above exception, another exception occurred:
[2025-08-29T15:51:50.867+0000] {subprocess.py:93} INFO - 
[2025-08-29T15:51:50.867+0000] {subprocess.py:93} INFO - Traceback (most recent call last):
[2025-08-29T15:51:50.867+0000] {subprocess.py:93} INFO -   File "/opt/***/scripts/train_model.py", line 57, in <module>
[2025-08-29T15:51:50.868+0000] {subprocess.py:93} INFO -     train_sales_model()
[2025-08-29T15:51:50.868+0000] {subprocess.py:93} INFO -   File "/opt/***/scripts/train_model.py", line 17, in train_sales_model
[2025-08-29T15:51:50.869+0000] {subprocess.py:93} INFO -     mlflow.set_experiment("Retail Sales Forecasting - Docker")
[2025-08-29T15:51:50.869+0000] {subprocess.py:93} INFO -   File "/home/***/.local/lib/python3.12/site-packages/mlflow/tracking/fluent.py", line 183, in set_experiment
[2025-08-29T15:51:50.869+0000] {subprocess.py:93} INFO -     experiment = client.get_experiment_by_name(experiment_name)
[2025-08-29T15:51:50.870+0000] {subprocess.py:93} INFO -                  ^^^^^^^^^^^^^^^^^^^^^^^^^^^^^^^^^^^^^^^^^^^^^^
[2025-08-29T15:51:50.870+0000] {subprocess.py:93} INFO -   File "/home/***/.local/lib/python3.12/site-packages/mlflow/tracking/_tracking_service/client.py", line 270, in get_experiment_by_name
[2025-08-29T15:51:50.871+0000] {subprocess.py:93} INFO -     return self.store.get_experiment_by_name(name)
[2025-08-29T15:51:50.871+0000] {subprocess.py:93} INFO -            ^^^^^^^^^^^^^^^^^^^^^^^^^^^^^^^^^^^^^^^
[2025-08-29T15:51:50.872+0000] {subprocess.py:93} INFO -   File "/home/***/.local/lib/python3.12/site-packages/mlflow/store/tracking/rest_store.py", line 757, in get_experiment_by_name
[2025-08-29T15:51:50.872+0000] {subprocess.py:93} INFO -     response_proto = self._call_endpoint(GetExperimentByName, req_body)
[2025-08-29T15:51:50.872+0000] {subprocess.py:93} INFO -                      ^^^^^^^^^^^^^^^^^^^^^^^^^^^^^^^^^^^^^^^^^^^^^^^^^^
[2025-08-29T15:51:50.873+0000] {subprocess.py:93} INFO -   File "/home/***/.local/lib/python3.12/site-packages/mlflow/store/tracking/rest_store.py", line 134, in _call_endpoint
[2025-08-29T15:51:50.873+0000] {subprocess.py:93} INFO -     return call_endpoint(
[2025-08-29T15:51:50.874+0000] {subprocess.py:93} INFO -            ^^^^^^^^^^^^^^
[2025-08-29T15:51:50.874+0000] {subprocess.py:93} INFO -   File "/home/***/.local/lib/python3.12/site-packages/mlflow/utils/rest_utils.py", line 549, in call_endpoint
[2025-08-29T15:51:50.875+0000] {subprocess.py:93} INFO -     response = http_request(**call_kwargs)
[2025-08-29T15:51:50.875+0000] {subprocess.py:93} INFO -                ^^^^^^^^^^^^^^^^^^^^^^^^^^^
[2025-08-29T15:51:50.876+0000] {subprocess.py:93} INFO -   File "/home/***/.local/lib/python3.12/site-packages/mlflow/utils/rest_utils.py", line 253, in http_request
[2025-08-29T15:51:50.876+0000] {subprocess.py:93} INFO -     raise MlflowException(f"API request to {url} failed with exception {e}")
[2025-08-29T15:51:50.877+0000] {subprocess.py:93} INFO - mlflow.exceptions.MlflowException: API request to http://mlflow-server:5000/api/2.0/mlflow/experiments/get-by-name failed with exception HTTPConnectionPool(host='mlflow-server', port=5000): Max retries exceeded with url: /api/2.0/mlflow/experiments/get-by-name?experiment_name=Retail+Sales+Forecasting+-+Docker (Caused by NameResolutionError("<urllib3.connection.HTTPConnection object at 0x7ff5f663d160>: Failed to resolve 'mlflow-server' ([Errno -5] No address associated with hostname)"))
[2025-08-29T15:51:51.158+0000] {subprocess.py:97} INFO - Command exited with return code 1
[2025-08-29T15:51:51.159+0000] {taskinstance.py:441} INFO - ::group::Post task execution logs
[2025-08-29T15:51:51.169+0000] {taskinstance.py:2905} ERROR - Task failed with exception
Traceback (most recent call last):
  File "/home/airflow/.local/lib/python3.12/site-packages/airflow/models/taskinstance.py", line 465, in _execute_task
    result = _execute_callable(context=context, **execute_callable_kwargs)
             ^^^^^^^^^^^^^^^^^^^^^^^^^^^^^^^^^^^^^^^^^^^^^^^^^^^^^^^^^^^^^
  File "/home/airflow/.local/lib/python3.12/site-packages/airflow/models/taskinstance.py", line 432, in _execute_callable
    return execute_callable(context=context, **execute_callable_kwargs)
           ^^^^^^^^^^^^^^^^^^^^^^^^^^^^^^^^^^^^^^^^^^^^^^^^^^^^^^^^^^^^
  File "/home/airflow/.local/lib/python3.12/site-packages/airflow/models/baseoperator.py", line 401, in wrapper
    return func(self, *args, **kwargs)
           ^^^^^^^^^^^^^^^^^^^^^^^^^^^
  File "/home/airflow/.local/lib/python3.12/site-packages/airflow/operators/bash.py", line 243, in execute
    raise AirflowException(
airflow.exceptions.AirflowException: Bash command failed. The command returned a non-zero exit code 1.
[2025-08-29T15:51:51.173+0000] {taskinstance.py:1206} INFO - Marking task as FAILED. dag_id=retail_sales_training_pipeline, task_id=train_initial_model, run_id=manual__2025-08-29T15:47:00.749670+00:00, execution_date=20250829T154700, start_date=20250829T154708, end_date=20250829T155151
[2025-08-29T15:51:51.191+0000] {standard_task_runner.py:110} ERROR - Failed to execute job 12 for task train_initial_model (Bash command failed. The command returned a non-zero exit code 1.; 222)
[2025-08-29T15:51:51.235+0000] {local_task_job_runner.py:240} INFO - Task exited with return code 1
[2025-08-29T15:51:51.251+0000] {taskinstance.py:3503} INFO - 0 downstream tasks scheduled from follow-on schedule check
[2025-08-29T15:51:51.255+0000] {local_task_job_runner.py:222} INFO - ::endgroup::
